Workbook

Sheet LS results
C1: mprior | D1: um(20) | E1: diag(CM) | F1: diff | G1: chi^2 | M1: dobs | N1: fm | O1: diag(CD) | P1: chi^2
B2: 1 | C2: 0.9995 | D2: 0.99923913 | E2: 0.0025 | F2: =C2-D2 -> 0.00026087194 | G2: =F2^2/E2 -> 2.7221668e-05 | M2: 5.6016186 | N2: 5.6021952 | O2: 3.230775e-07 | P2: =(M2-N2)^2/O2 -> 1.0289069
B3: 2 | C3: 100.18 | D3: 100.2329 | E3: 0.25 | F3: =C3-D3 -> -0.052904413 | G3: =F3^2/E3 -> 0.011195507 | M3: 2.6209444 | N3: 2.6206851 | O3: 7.5985025e-08 | P3: =(M3-N3)^2/O3 -> 0.88495195 | S3: covMeas:
A4: g205 | B4: 3 | C4: 0.9995 | D4: 0.99937195 | E4: 0.0025 | F4: =C4-D4 -> 0.00012805036 | G4: =F4^2/E4 -> 6.5587578e-06 | M4: 5.6188561 | N4: 5.6203238 | O4: 3.5883641e-07 | P4: =(M4-N4)^2/O4 -> 6.003611 | S4: 8.9619356e-11 | T4: 4.923454e-09
B5: 4 | C5: 0.9995 | D5: 0.99952751 | E5: 0.0025 | F5: =C5-D5 -> -2.7514779e-05 | G5: =F5^2/E5 -> 3.0282522e-07 | M5: 1.0051626 | N5: 1.0046582 | O5: 2.7053165e-08 | P5: =(M5-N5)^2/O5 -> 9.4049646 | S5: 4.9234391e-09 | T5: 1.2018978e-06
B6: 5 | C6: 0.9995 | D6: 0.99941818 | E6: 0.0025 | F6: =C6-D6 -> 8.1820376e-05 | G6: =F6^2/E6 -> 2.6778296e-06 | M6: 5.6063673 | N6: 5.6066603 | O6: 2.6607803e-07 | P6: =(M6-N6)^2/O6 -> 0.32262216
B7: 6 | C7: 0.9995 | D7: 0.99969653 | E7: 0.0025 | F7: =C7-D7 -> -0.00019652734 | G7: =F7^2/E7 -> 1.5449197e-05 | M7: 2.62198 | N7: 2.6220276 | O7: 4.0048572e-08 | P7: =(M7-N7)^2/O7 -> 0.056672999 | S7: covsys:
B8: 7 | C8: 0.9995 | D8: 0.9995359 | E8: 0.0025 | F8: =C8-D8 -> -3.5904011e-05 | G8: =F8^2/E8 -> 5.1563919e-07 | M8: 5.6217306 | N8: 5.6219462 | O8: 2.5084642e-07 | P8: =(M8-N8)^2/O8 -> 0.18518801 | S8: 7.0429689e-08 | T8: -5.6676455e-06
B9: 8 | C9: 0.9995 | D9: 0.99894302 | E9: 0.0025 | F9: =C9-D9 -> 0.00055697545 | G9: =F9^2/E9 -> 0.00012408866 | M9: 1.003841 | N9: 1.003913 | O9: 1.4839805e-08 | P9: =(M9-N9)^2/O9 -> 0.34916426 | S9: -5.6676455e-06 | T9: 0.00054242784
B10: 9 | C10: 0.9995 | D10: 0.99922454 | E10: 0.0025 | F10: =C10-D10 -> 0.00027545978 | G10: =F10^2/E10 -> 3.0351235e-05 | M10: 5.6088549 | N10: 5.6085169 | O10: 1.9108379e-07 | P10: =(M10-N10)^2/O10 -> 0.59765299
B11: 10 | C11: 0.9995 | D11: 0.99981826 | E11: 0.0025 | F11: =C11-D11 -> -0.00031825998 | G11: =F11^2/E11 -> 4.0515767e-05 | M11: 2.6229663 | N11: 2.6225857 | O11: 4.3914911e-08 | P11: =(M11-N11)^2/O11 -> 3.2974517 | S11: covTot:
B12: 11 | C12: 0.9995 | D12: 0.99856599 | E12: 0.0025 | F12: =C12-D12 -> 0.0009340085 | G12: =F12^2/E12 -> 0.00034894875 | M12: 5.6230864 | N12: 5.6226205 | O12: 1.728681e-07 | P12: =(M12-N12)^2/O12 -> 1.2557317 | S12: =S4+S8 -> 7.0519308e-08 | T12: =T4+T8 -> -5.662722e-06
B13: 12 | C13: 0.9995 | D13: 0.99902063 | E13: 0.0025 | F13: =C13-D13 -> 0.00047936913 | G13: =F13^2/E13 -> 9.1917905e-05 | M13: 1.0034563 | N13: 1.0036035 | O13: 1.262794e-08 | P13: =(M13-N13)^2/O13 -> 1.7150598 | S13: =S5+S9 -> -5.662722e-06 | T13: =T5+T9 -> 0.00054362974
B14: 13 | C14: 0.9995 | D14: 1.000107 | E14: 0.0025 | F14: =C14-D14 -> -0.00060698272 | G14: =F14^2/E14 -> 0.00014737121 | M14: 5.6109821 | N14: 5.6108862 | O14: 1.9671073e-07 | P14: =(M14-N14)^2/O14 -> 0.046756778
B15: 14 | C15: 0.9995 | D15: 1.0000594 | E15: 0.0025 | F15: =C15-D15 -> -0.00055936087 | G15: =F15^2/E15 -> 0.00012515383 | M15: 2.6231195 | N15: 2.6232978 | O15: 4.1971731e-08 | P15: =(M15-N15)^2/O15 -> 0.75727003 | S15: 2-sigma meas | T15: 2-sigma abs | U15: 2-sigma ppm | V15: rho
B16: 15 | C16: 0.9995 | D16: 0.99984453 | E16: 0.0025 | F16: =C16-D16 -> -0.00034452764 | G16: =F16^2/E16 -> 4.7479718e-05 | M16: 5.623592 | N16: 5.6234808 | O16: 2.0173946e-07 | P16: =(M16-N16)^2/O16 -> 0.06127021 | R16: =D2 -> 0.99923913 | S16: =2*SQRT(S4) -> 1.89335e-05 | T16: =2*SQRT(S12) -> 0.00053110944 | U16: =T16/R16*10^6 -> 531.51385 | V16: =T12/SQRT(S12*T13) -> -0.91457562
B17: 16 | C17: 0.9995 | D17: 1.000178 | E17: 0.0025 | F17: =C17-D17 -> -0.00067797712 | G17: =F17^2/E17 -> 0.00018386119 | M17: 1.0033153 | N17: 1.0032088 | O17: 1.6034859e-08 | P17: =(M17-N17)^2/O17 -> 0.70726233 | R17: =D3 -> 100.2329 | S17: =2*SQRT(T5) -> 0.002192622 | T17: =2*SQRT(T13) -> 0.046631738 | U17: =T17/R17*10^6 -> 465.23383
B18: 17 | C18: 0.9995 | D18: 0.9997604 | E18: 0.0025 | F18: =C18-D18 -> -0.00026040356 | G18: =F18^2/E18 -> 2.7124006e-05 | M18: 5.6146422 | N18: 5.6137683 | O18: 5.1240887e-07 | P18: =(M18-N18)^2/O18 -> 1.4902248
B19: 18 | C19: 0.9995 | D19: 0.99973444 | E19: 0.0025 | F19: =C19-D19 -> -0.00023443562 | G19: =F19^2/E19 -> 2.1984023e-05 | M19: 2.6245562 | N19: 2.6241639 | O19: 1.1370354e-07 | P19: =(M19-N19)^2/O19 -> 1.3531069
B20: 19 | C20: 0.9995 | D20: 0.99963033 | E20: 0.0025 | F20: =C20-D20 -> -0.00013033241 | G20: =F20^2/E20 -> 6.7946149e-06 | M20: 5.6259698 | N20: 5.6245271 | O20: 4.8181423e-07 | P20: =(M20-N20)^2/O20 -> 4.3197807
B21: 20 | C21: 0.9995 | D21: 0.9995632 | E21: 0.0025 | F21: =C21-D21 -> -6.3201352e-05 | G21: =F21^2/E21 -> 1.5977644e-06 | M21: 1.0022983 | N21: 1.0027291 | O21: 6.7878185e-09 | P21: =(M21-N21)^2/O21 -> 27.34671
B22: 21 | C22: 0.9995 | D22: 0.99810846 | E22: 0.0025 | F22: =C22-D22 -> 0.0013915367 | G22: =F22^2/E22 -> 0.00077454972 | M22: 5.6145857 | N22: 5.6140891 | O22: 1.7586966e-07 | P22: =(M22-N22)^2/O22 -> 1.4019091
B23: 22 | C23: 0.9995 | D23: 0.99929481 | E23: 0.0025 | F23: =C23-D23 -> 0.00020519042 | G23: =F23^2/E23 -> 1.6841243e-05 | M23: 2.6246489 | N23: 2.6242603 | O23: 4.6574508e-08 | P23: =(M23-N23)^2/O23 -> 3.2416748
B24: 23 | C24: 0.9995 | D24: 0.99942372 | E24: 0.0025 | F24: =C24-D24 -> 7.6279545e-05 | G24: =F24^2/E24 -> 2.3274276e-06 | M24: 5.6250753 | N24: 5.6246435 | O24: 1.9294238e-07 | P24: =(M24-N24)^2/O24 -> 0.96609125
B25: 24 | C25: 0.9995 | D25: 0.99884479 | E25: 0.0025 | F25: =C25-D25 -> 0.00065521374 | G25: =F25^2/E25 -> 0.00017172202 | M25: 1.002925 | N25: 1.0026757 | O25: 2.1850344e-08 | P25: =(M25-N25)^2/O25 -> 2.8433754
B26: 25 | C26: 0.9995 | D26: 0.99888306 | E26: 0.0025 | F26: =C26-D26 -> 0.00061693973 | G26: =F26^2/E26 -> 0.00015224585 | M26: 5.6149029 | N26: 5.6153576 | O26: 1.6482519e-07 | P26: =(M26-N26)^2/O26 -> 1.2546161
B27: 26 | C27: 0.9995 | D27: 0.99971313 | E27: 0.0025 | F27: =C27-D27 -> -0.00021312535 | G27: =F27^2/E27 -> 1.8168965e-05 | M27: 2.6243885 | N27: 2.6246415 | O27: 7.3570734e-08 | P27: =(M27-N27)^2/O27 -> 0.8696621
B28: 27 | C28: 0.9995 | D28: 0.9995403 | E28: 0.0025 | F28: =C28-D28 -> -4.0301691e-05 | G28: =F28^2/E28 -> 6.4969053e-07 | M28: 5.6244034 | N28: 5.6251039 | O28: 2.6170907e-07 | P28: =(M28-N28)^2/O28 -> 1.8748594
B29: 28 | C29: 0.9995 | D29: 0.99938082 | E29: 0.0025 | F29: =C29-D29 -> 0.00011918439 | G29: =F29^2/E29 -> 5.6819679e-06 | M29: 1.0025609 | N29: 1.0024648 | O29: 1.7220612e-08 | P29: =(M29-N29)^2/O29 -> 0.53710724
... B49: 48 | C49: 0.9995 | D49: 0.99908714 | E49: 0.0025 | F49: =C49-D49 -> 0.00041285968 | G49: =F49^2/E49 -> 6.8181246e-05 | M49: 1.0013533 | N49: 1.0012496 | O49: 8.3540761e-09 | P49: =(M49-N49)^2/O49 -> 1.2871038
A50: g207 | B50: 49 | C50: 0.9995 | D50: 0.99940567 | E50: 0.0025 | F50: =C50-D50 -> 9.4327984e-05 | G50: =F50^2/E50 -> 3.5591074e-06 | M50: 5.6244174 | N50: 5.624305 | O50: 7.9893248e-08 | P50: =(M50-N50)^2/O50 -> 0.15811426
B51: 50 | C51: 0.9995 | D51: 0.99931014 | E51: 0.0025 | F51: =C51-D51 -> 0.0001898645 | G51: =F51^2/E51 -> 1.4419411e-05 | M51: 2.6271905 | N51: 2.627329 | O51: 2.7491968e-08 | P51: =(M51-N51)^2/O51 -> 0.69790075
B52: 51 | C52: 0.9995 | D52: 0.99948786 | E52: 0.0025 | F52: =C52-D52 -> 1.2137009e-05 | G52: =F52^2/E52 -> 5.8922793e-08 | M52: 5.6284969 | N52: 5.6283491 | O52: 7.3406225e-08 | P52: =(M52-N52)^2/O52 -> 0.29730334
B53: 52 | C53: 0.9995 | D53: 0.99932874 | E53: 0.0025 | F53: =C53-D53 -> 0.00017126075 | G53: =F53^2/E53 -> 1.1732098e-05 | M53: 1.0011171 | N53: 1.0009794 | O53: 6.8592796e-09 | P53: =(M53-N53)^2/O53 -> 2.7653209
B54: 53 | C54: 0.9995 | D54: 0.99949187 | E54: 0.0025 | F54: =C54-D54 -> 8.1332779e-06 | G54: =F54^2/E54 -> 2.6460084e-08 | M54: 5.626484 | N54: 5.6262592 | O54: 2.4775636e-07 | P54: =(M54-N54)^2/O54 -> 0.20401977
B55: 54 | C55: 0.9995 | D55: 0.99934982 | E55: 0.0025 | F55: =C55-D55 -> 0.00015017746 | G55: =F55^2/E55 -> 9.0213078e-06 | M55: 2.6280018 | N55: 2.6279158 | O55: 4.9372467e-08 | P55: =(M55-N55)^2/O55 -> 0.15002389
B56: 55 | C56: 0.9995 | D56: 0.99944547 | E56: 0.0025 | F56: =C56-D56 -> 5.4525643e-05 | G56: =F56^2/E56 -> 1.1892183e-06 | M56: 5.6292936 | N56: 5.6290575 | O56: 2.0523014e-07 | P56: =(M56-N56)^2/O56 -> 0.27164511
B57: 56 | C57: 0.9995 | D57: 0.99799696 | E57: 0.0025 | F57: =C57-D57 -> 0.0015030437 | G57: =F57^2/E57 -> 0.00090365613 | M57: 1.0006297 | N57: 1.0006556 | O57: 6.1978613e-09 | P57: =(M57-N57)^2/O57 -> 0.10773439
B58: 57 | C58: 0.9995 | D58: 0.99932117 | E58: 0.0025 | F58: =C58-D58 -> 0.00017882992 | G58: =F58^2/E58 -> 1.2792056e-05 | M58: 5.627539 | N58: 5.6269745 | O58: 1.9178888e-07 | P58: =(M58-N58)^2/O58 -> 1.6620494
B59: 58 | C59: 0.9995 | D59: 0.99900299 | E59: 0.0025 | F59: =C59-D59 -> 0.00049700676 | G59: =F59^2/E59 -> 9.8806289e-05 | M59: 2.628274 | N59: 2.6281305 | O59: 3.4808236e-08 | P59: =(M59-N59)^2/O59 -> 0.59123485
...

Sheet MC summary
B1: name | C1: values | D1: 2-sigma | E1: 2-sigma ppm
A2: ET535 | B2: 204/205 | C2: 8.9730985e-05 | D2: 1.8374032e-05
B3: 206/205 | C3: 0.00038307456 | D3: 0.00034434402
B4: 207/205 | C4: 0.00029137677 | D4: 0.00028652004
B5: 208/205 | C5: 0.00073246688 | D5: 0.00071165414
A6: ET2535 | B6: 204/205 | C6: 0.00010529586 | D6: 1.874553e-05
B7: 206/205 | C7: 0.00048799602 | D7: 0.00034004213
B8: 207/205 | C8: 0.00043695472 | D8: 0.00028182416
B9: 208/205 | C9: 0.0010535738 | D9: 0.00068494805
A10: CRM 115 | B10: 238/235 | C10: 491.54852 | D10: 0.085119747 | E10: =D10/C10*10^6 -> 173.16652
A11: CRM 112a | B11: 238/235 | C11: 137.8412 | D11: 0.023559007 | E11: =D11/C11*10^6 -> 170.91411
A12: ET535 | B12: 233/235 | C12: 0.9950618 | D12: 0.00010749504 | E12: =D12/C12*10^6 -> 108.02851
B13: 238/235 | C13: 0.0030799284 | D13: 7.9544358e-07 | E13: =D13/C13*10^6 -> 258.26691
A14: NBS 981 | B14: 204/206 | C14: 0.059007343 | D14: 2.1848329e-05 | E14: =D14/C14*10^6 -> 370.26457
B15: 207/206 | C15: 0.91468284 | D15: 0.00014531625 | E15: =D15/C15*10^6 -> 158.87064
B16: 208/206 | C16: 2.1680997 | D16: 0.00078779025 | E16: =D16/C16*10^6 -> 363.35518
A17: NBS 982 | B17: 204/206 | C17: 0.027205848 | D17: 1.0201734e-05 | E17: =D17/C17*10^6 -> 374.98313
B18: 207/206 | C18: 0.46696702 | D18: 8.1635643e-05 | E18: =D18/C18*10^6 -> 174.821
B19: 208/206 | C19: 1.0002496 | D19: 0.00038028744 | E19: =D19/C19*10^6 -> 380.19254
A20: Puratronic | B20: 204/206 | C20: 0.054886008 | D20: 2.093947e-05 | E20: =D20/C20*10^6 -> 381.50835
B21: 207/206 | C21: 0.85672018 | D21: 0.00014748012 | E21: =D21/C21*10^6 -> 172.14503
B22: 208/206 | C22: 2.1022727 | D22: 0.00078200191 | E22: =D22/C22*10^6 -> 371.9793
A23: ETsoln | B23: 206/238 | C23: 0.016716898 | D23: 3.8551147e-06 | E23: =D23/C23*10^6 -> 230.61185
A24: RPsoln | B24: 206/238 | C24: 0.094040434 | D24: 1.8033135e-05 | E24: =D24/C24*10^6 -> 191.75938
A25: JMMsoln | B25: 206/238 | C25: 0.049815379 | D25: 1.1743196e-05 | E25: =D25/C25*10^6 -> 235.73436
A26: ET2535 | B26: 202/205 | C26: 0.99923702 | D26: 0.00053077185 | E26: =D26/C26*10^6 -> 531.17712
A27: ET(2)535 | B27: 235/205 | C27: 100.23259 | D27: 0.046580161 | E27: =D27/C27*10^6 -> 464.72073
C29: 2.5285624e+08 | D29: 69338.05 | E29: =D29/C29*10^6 -> 274.21925

Sheet r85z
B1: assessing partial derivatives of 235/205 wrt IRMM 3636 U parameters
H2: J1 | J2: IRMM 3636 | O2: Covariance IRMM 3636 | Q2: IRMM 3636
B3: r233_235t | C3: 235/205t | E3: d55t_d35t | J3: 233/236 | K3: 234/236 | L3: 235/236 | M3: 238/236 | Q3: 233/236 | R3: 234/236 | S3: 235/236 | T3: 238/236
B4: 0.99506218 | C4: 100.2329 | E4: =(C5-C4)/(B5-B4) -> 154.99418 | H4: r85_U500 | I4: 238/235 | J4: -1.0195797 | K4: 0.0023910778 | L4: 0.83929915 | M4: -0.84015693 | O4: IRMM 3636 | P4: 233/236 | Q4: 6.4e-09 | R4: 0 | S4: 0 | T4: 0
B5: 0.9950612 | C5: 100.23275 | H5: r85_112a | I5: 238/235 | J5: -135.28724 | K5: 0 | L5: 434.49408 | M5: -3.1521123 | P5: 234/236 | Q5: 0 | R5: 5.76e-14 | S5: 0 | T5: 0
H6: r85_115 | I6: 238/235 | J6: -482.65484 | K6: 0 | L6: 1656.117 | M6: -3.3845968 | P6: 235/236 | Q6: 0 | R6: 0 | S6: 1.369e-15 | T6: 0
B7: r238_235t | C7: 235/205t | E7: d55t_d85t | H7: r85z | I7: 238/25 | J7: -134.15418 | K7: 0 | L7: 308.30363 | M7: -2.2367059 | P7: 238/236 | Q7: 0 | R7: 0 | S7: 0 | T7: 3.61e-14
B8: 0.0030799297 | C8: =$C$4 -> 100.2329 | E8: =(C9-C8)/(B9-B8) -> 140.93097
B9: 0.0030799266 | C9: 100.2329 | H9: J2 | J9: r85_U500 | K9: r85_112a | L9: r85_115 | M9: r85z
J10: 238/235 | K10: 238/235 | L10: 238/235 | M10: 238/25
B11: r238_235-112 | E11: d55t_d85_112a | H11: ET535 | I11: 233/235t | J11: -0.527905 | K11: -0.00097935 | L11: 0 | M11: 0
B12: 137.84136 | C12: =$C$4 -> 100.2329 | E12: =(C13-C12)/(B13-B12) -> 0.022902328 | I12: 238/235t | J12: 0.001760186 | K12: 8.22529e-06 | L12: 0 | M12: 0
B13: 137.84122 | C13: 100.2329 | H13: sample | I13: 238/235z | J13: 0 | K13: 0 | L13: 0 | M13: 1
H14: RP | I14: 206/238g | J14: 0 | K14: =-4.8519100522975*10^-6 -> -4.8519101e-06 | L14: 0 | M14: 0
B15: r238_235-115 | E15: d55t_d85_115 | H15: ET | I15: 206/238g | J15: 0 | K15: =-8.62488785450637*10^-7 -> -8.6248879e-07 | L15: 0 | M15: 0
B16: 491.54806 | C16: =$C$4 -> 100.2329 | E16: =(C17-C16)/(B17-B16) -> 0.00022461586 | H16: JMM | I16: 206/238g | J16: 0 | K16: 0 | L16: =-2.03161*10^-7 -> -2.03161e-07 | M16: 0
B17: 491.54757 | C17: 100.2329 | H17: r85_U500 | I17: 238/235 | J17: 1 | K17: 0 | L17: 0 | M17: 0
H18: r85_112a | I18: 238/235 | J18: 0 | K18: 1 | L18: 0 | M18: 0
B19: RP 206/238 | E19: d55t_d85_115 | H19: r85_115 | I19: 238/235 | J19: 0 | K19: 0 | L19: 1 | M19: 0
B20: 0.094040437 | C20: =$C$4 -> 100.2329 | E20: =(C21-C20)/(B21-B20) -> -485.82394
B21: 0.094040342 | C21: 100.23295
H22: J3 | J22: ET535 | L22: sample | M22: RP | N22: ET | O22: JMM | P22: r85_U500 | Q22: r85_112a | R22: r85_115
B23: ET 206/238 | E23: d55t_d85_115 | J23: 233/235t | K23: 238/235t | L23: 238/235z | M23: 206/238g | N23: 206/238g | O23: 206/238g | P23: 238/235 | Q23: 238/235 | R23: 238/235
B24: 0.016716885 | C24: =$C$4 -> 100.2329 | E24: =(C25-C24)/(B25-B24) -> -1489.6132 | H24: ET535 | I24: 233/235t | J24: 1 | K24: 0 | L24: 0 | M24: 0 | N24: 0 | O24: 0 | P24: 0 | Q24: 0 | R24: 0
B25: 0.016716868 | C25: 100.23293 | I25: 238/235t | J25: 0 | K25: 1 | L25: 0 | M25: 0 | N25: 0 | O25: 0 | P25: 0 | Q25: 0 | R25: 0
I26: r235/205t | J26: =E4 -> 154.99418 | K26: =E8 -> 140.93097 | L26: 0 | M26: =E20 -> -485.82394 | N26: =E24 -> -1489.6132 | O26: =E28 -> -595.07022 | P26: 0 | Q26: =E12 -> 0.022902328 | R26: =E16 -> 0.00022461586
B27: JMM 206/238 | E27: d55t_d85_115 | H27: sample | I27: 238/235z | J27: 0 | K27: 0 | L27: 1 | M27: 0 | N27: 0 | O27: 0 | P27: 0 | Q27: 0 | R27: 0
B28: 0.049815399 | C28: =$C$4 -> 100.2329 | E28: =(C29-C28)/(B29-B28) -> -595.07022 | H28: RP | I28: 206/238g | J28: 0 | K28: 0 | L28: 0 | M28: 1 | N28: 0 | O28: 0 | P28: 0 | Q28: 0 | R28: 0
B29: 0.049815349 | C29: 100.23293 | H29: ET | I29: 206/238g | J29: 0 | K29: 0 | L29: 0 | M29: 0 | N29: 1 | O29: 0 | P29: 0 | Q29: 0 | R29: 0
H30: JMM | I30: 206/238g | J30: 0 | K30: 0 | L30: 0 | M30: 0 | N30: 0 | O30: 1 | P30: 0 | Q30: 0 | R30: 0
B31: dRP-206/238_dr85g_112a | H31: r85_U500 | I31: 238/235 | J31: 0 | K31: 0 | L31: 0 | M31: 0 | N31: 0 | O31: 0 | P31: 1 | Q31: 0 | R31: 0
B32: =-4.8519100522975*10^-6 -> -4.8519101e-06 | H32: r85_112a | I32: 238/235 | J32: 0 | K32: 0 | L32: 0 | M32: 0 | N32: 0 | O32: 0 | P32: 0 | Q32: 1 | R32: 0
H33: r85_115 | I33: 238/235 | J33: 0 | K33: 0 | L33: 0 | M33: 0 | N33: 0 | O33: 0 | P33: 0 | Q33: 0 | R33: 1
B34: dET-206/238_dr85g_112a
B35: =-8.62488785450637*10^-7 -> -8.6248879e-07 | H35: J3J2J1 | J35: IRMM 3636
J36: 233/236 | K36: 234/236 | L36: 235/236 | M36: 238/236
B37: dJMM-206/238_dr85g_115 | H37: ET535 | I37: 233/235t | J37: {=MMULT(MMULT(J24:R33,J11:M19),J4:M7)} -> 0.67073476 | K37: -0.0012622619 | L37: -0.868592 | M37: 0.44661007
B38: =-2.03161*10^-7 -> -2.03161e-07 | I38: 238/235t | J38: -0.0029074266 | K38: 4.2087416e-06 | L38: 0.0050511624 | M38: -0.0015047595
I39: r235/205t | J39: 99.792373 | K39: -0.19505011 | L39: -121.8093 | M39: 68.925054
H40: sample | I40: 238/235z | J40: -134.15418 | K40: 0 | L40: 308.30363 | M40: -2.2367059
...

Sheet Sheet4

Sheet covTotal
K1: Covariance Matrix for MC trials (includes only systematic unct for 202/205 and 235/205) | M1: ET535 | Q1: ET2535 | U1: RP DU | V1: CRM112a | W1: ET tracers | Y1: NBS 981 | AB1: NBS 982 | AE1: Puratronic Pb | AH1: ET | AI1: RP | AJ1: JMM | AK1: ET tracers
M2: 204/205 | N2: 206/205 | O2: 207/205 | P2: 208/205 | Q2: 204/205 | R2: 206/205 | S2: 207/205 | T2: 208/205 | U2: 238/235 | V2: 238/235 | W2: 233/235 | X2: 238/235 | Y2: 204/206 | Z2: 207/206 | AA2: 208/206 | AB2: 204/206 | AC2: 207/206 | AD2: 208/206 | AE2: 204/206 | AF2: 207/206 | AG2: 208/206 | AH2: 206/238g | AI2: 206/238g | AJ2: 206/238g | AK2: 202/205 | AL2: 235/205
K3: ET535 | L3: 204/205 | M3: =covAll!C3 -> 8.4401259e-11 | N3: =covAll!D3 -> 1.5541603e-09 | O3: =covAll!E3 -> 1.3041691e-09 | P3: =covAll!F3 -> 3.1932364e-09 | Q3: =covAll!G3 -> 2.0206838e-12 | R3: =covAll!H3 -> 3.4280094e-11 | S3: =covAll!I3 -> 2.9582367e-11 | T3: =covAll!J3 -> 7.0834598e-11 | ... AL3: =covAll!AB3 -> -5.7932656e-09
L4: 206/205 | M4: =covAll!C4 -> 1.5541603e-09 | N4: =covAll!D4 -> 2.9643201e-08 | O4: =covAll!E4 -> 2.4477357e-08 | P4: =covAll!F4 -> 6.0583378e-08 | Q4: =covAll!G4 -> 4.0956018e-11 | R4: =covAll!H4 -> 7.0629015e-10 | S4: =covAll!I4 -> 6.0856147e-10 | T4: =covAll!J4 -> 1.4691506e-09 | ... AL4: =covAll!AB4 -> -1.2752518e-07
L5: 207/205 | M5: =covAll!C5 -> 1.3041691e-09 | N5: =covAll!D5 -> 2.4477357e-08 | O5: =covAll!E5 -> 2.0523433e-08 | P5: =covAll!F5 -> 5.061429e-08 | Q5: =covAll!G5 -> 3.499379e-11 | R5: =covAll!H5 -> 6.0702033e-10 | S5: =covAll!I5 -> 5.2137398e-10 | T5: =covAll!J5 -> 1.2575324e-09 | ... AL5: =covAll!AB5 -> -1.0127085e-07
L6: 208/205 | M6: =covAll!C6 -> 3.1932364e-09 | N6: =covAll!D6 -> 6.0583378e-08 | O6: =covAll!E6 -> 5.061429e-08 | P6: =covAll!F6 -> 1.2661291e-07 | Q6: =covAll!G6 -> 8.3566949e-11 | R6: =covAll!H6 -> 1.4418618e-09 | S6: =covAll!I6 -> 1.2400239e-09 | T6: =covAll!J6 -> 2.9980738e-09 | ... AL6: =covAll!AB6 -> -2.8391472e-07
K7: ET2535 | L7: 204/205 | M7: =covAll!C7 -> 2.0206838e-12 | N7: =covAll!D7 -> 4.0956018e-11 | O7: =covAll!E7 -> 3.499379e-11 | P7: =covAll!F7 -> 8.3566949e-11 | Q7: =covAll!G7 -> 8.7848722e-11 | R7: =covAll!H7 -> 1.5908858e-09 | S7: =covAll!I7 -> 1.3195772e-09 | T7: =covAll!J7 -> 3.202935e-09 | ... AL7: =covAll!AB7 -> -1.3624037e-09
L8: 206/205 | M8: =covAll!C8 -> 3.4280094e-11 | N8: =covAll!D8 -> 7.0629015e-10 | O8: =covAll!E8 -> 6.0702033e-10 | P8: =covAll!F8 -> 1.4418618e-09 | Q8: =covAll!G8 -> 1.5908858e-09 | R8: =covAll!H8 -> 2.8907162e-08 | S8: =covAll!I8 -> 2.3940042e-08 | T8: =covAll!J8 -> 5.8160209e-08 | ... AL8: =covAll!AB8 -> -2.6582354e-08
L9: 207/205 | M9: =covAll!C9 -> 2.9582367e-11 | N9: =covAll!D9 -> 6.0856147e-10 | O9: =covAll!E9 -> 5.2137398e-10 | P9: =covAll!F9 -> 1.2400239e-09 | Q9: =covAll!G9 -> 1.3195772e-09 | R9: =covAll!H9 -> 2.3940042e-08 | S9: =covAll!I9 -> 1.9856214e-08 | T9: =covAll!J9 -> 4.822575e-08 | ... AL9: =covAll!AB9 -> -2.2469068e-08
L10: 208/205 | M10: =covAll!C10 -> 7.0834598e-11 | N10: =covAll!D10 -> 1.4691506e-09 | O10: =covAll!E10 -> 1.2575324e-09 | P10: =covAll!F10 -> 2.9980738e-09 | Q10: =covAll!G10 -> 3.202935e-09 | R10: =covAll!H10 -> 5.8160209e-08 | S10: =covAll!I10 -> 4.822575e-08 | T10: =covAll!J10 -> 1.1728846e-07 | ... AL10: =covAll!AB10 -> -4.9340079e-08
K11: RP DU | L11: 238/235 | M11: =covAll!C11 -> 3.4511769e-09 | N11: =covAll!D11 -> 6.0096317e-08 | O11: =covAll!E11 -> 4.3662818e-08 | P11: =covAll!F11 -> 3.8017982e-08 | Q11: =covAll!G11 -> -1.0413434e-09 | R11: =covAll!H11 -> -1.934794e-08 | S11: =covAll!I11 -> -1.1940629e-08 | T11: =covAll!J11 -> -5.3169322e-08 | ... AL11: =covAll!AB11 -> -0.00032597222
K12: CRM112a | L12: 238/235 | M12: =covAll!C12 -> 3.6041121e-09 | N12: =covAll!D12 -> 6.5224032e-08 | O12: =covAll!E12 -> 5.4669682e-08 | P12: =covAll!F12 -> 1.1278997e-07 | Q12: =covAll!G12 -> -4.2772699e-10 | R12: =covAll!H12 -> -8.1360571e-09 | S12: =covAll!I12 -> -5.0733976e-09 | T12: =covAll!J12 -> -1.7021053e-08 | ... AL12: =covAll!AB12 -> -9.2077836e-05
K13: ET tracers | L13: 233/235 | M13: =covAll!C13 -> -1.2805695e-11 | N13: =covAll!D13 -> -2.3167409e-10 | O13: =covAll!E13 -> -1.9789096e-10 | P13: =covAll!F13 -> -4.0531615e-10 | Q13: =covAll!G13 -> 4.610964e-13 | R13: =covAll!H13 -> 1.5724234e-11 | S13: =covAll!I13 -> 6.7713278e-12 | T13: =covAll!J13 -> 4.1774129e-11 | ... AL13: =covAll!AB13 -> 4.4618322e-07
L14: 238/235 | M14: =covAll!C14 -> -4.8913092e-15 | N14: =covAll!D14 -> 2.2899377e-14 | O14: =covAll!E14 -> -2.3897245e-15 | P14: =covAll!F14 -> -1.5431809e-13 | Q14: =covAll!G14 -> 5.5238195e-14 | R14: =covAll!H14 -> 1.1283289e-12 | S14: =covAll!I14 -> 9.0507676e-13 | T14: =covAll!J14 -> 2.295849e-12 | ... AL14: =covAll!AB14 -> -2.1274359e-09
K15: NBS 981 | L15: 204/206 | M15: =covAll!C15 -> -3.7990667e-13 | N15: =covAll!D15 -> 1.1732936e-12 | O15: =covAll!E15 -> 6.4940111e-13 | P15: =covAll!F15 -> 2.8200402e-11 | Q15: =covAll!G15 -> 1.6928661e-12 | R15: =covAll!H15 -> 3.1847588e-11 | S15: =covAll!I15 -> 2.6790185e-11 | T15: =covAll!J15 -> 6.5933468e-11 | ... AL15: =covAll!AB15 -> -2.325822e-07
L16: 207/206 | M16: =covAll!C16 -> 3.7607471e-12 | N16: =covAll!D16 -> 8.8824131e-12 | O16: =covAll!E16 -> 6.7097011e-12 | P16: =covAll!F16 -> -1.6100223e-10 | Q16: =covAll!G16 -> -1.0482122e-11 | R16: =covAll!H16 -> -1.9413496e-10 | S16: =covAll!I16 -> -1.6487177e-10 | T16: =covAll!J16 -> -3.9868408e-10 | ... AL16: =covAll!AB16 -> 1.4891812e-06
L17: 208/206 | M17: =covAll!C17 -> 1.5201564e-11 | N17: =covAll!D17 -> -5.7742548e-11 | O17: =covAll!E17 -> -3.2522737e-11 | P17: =covAll!F17 -> -1.0667809e-09 | Q17: =covAll!G17 -> -6.002277e-11 | R17: =covAll!H17 -> -1.1238861e-09 | S17: =covAll!I17 -> -9.4307706e-10 | T17: =covAll!J17 -> -2.3101609e-09 | ... AL17: =covAll!AB17 -> 8.2935988e-06
K18: NBS 982 | L18: 204/206 | M18: =covAll!C18 -> 1.5110591e-13 | N18: =covAll!D18 -> 7.6716014e-12 | O18: =covAll!E18 -> 6.7188019e-12 | P18: =covAll!F18 -> 2.9807683e-11 | Q18: =covAll!G18 -> 4.2634161e-13 | R18: =covAll!H18 -> 8.3536162e-12 | S18: =covAll!I18 -> 6.8317153e-12 | T18: =covAll!J18 -> 1.6666517e-11 | ... AL18: =covAll!AB18 -> -9.9146642e-08
L19: 207/206 | M19: =covAll!C19 -> -1.0398825e-12 | N19: =covAll!D19 -> -3.8574072e-11 | O19: =covAll!E19 -> -2.4440007e-11 | P19: =covAll!F19 -> -1.5251487e-10 | Q19: =covAll!G19 -> -1.0770441e-11 | R19: =covAll!H19 -> -2.002014e-10 | S19: =covAll!I19 -> -1.6613193e-10 | T19: =covAll!J19 -> -3.9809666e-10 | ... AL19: =covAll!AB19 -> 8.3592055e-07
L20: 208/206 | M20: =covAll!C20 -> 1.7431024e-13 | N20: =covAll!D20 -> -9.4826056e-11 | O20: =covAll!E20 -> -7.2843308e-11 | P20: =covAll!F20 -> -6.3397534e-10 | Q20: =covAll!G20 -> -5.076583e-11 | R20: =covAll!H20 -> -9.3694742e-10 | S20: =covAll!I20 -> -7.7809227e-10 | T20: =covAll!J20 -> -1.886617e-09 | ... AL20: =covAll!AB20 -> 4.1048319e-06
K21: Pur Pb | L21: 204/206 | M21: =covAll!C21 -> 1.2630877e-13 | N21: =covAll!D21 -> 1.2084213e-11 | O21: =covAll!E21 -> 8.7644765e-12 | P21: =covAll!F21 -> 4.4902623e-11 | Q21: =covAll!G21 -> 1.3565402e-12 | R21: =covAll!H21 -> 2.5542971e-11 | S21: =covAll!I21 -> 2.1668274e-11 | T21: =covAll!J21 -> 5.2867495e-11 | ... AL21: =covAll!AB21 -> -2.1870257e-07
L22: 207/206 | M22: =covAll!C22 -> -1.7534032e-13 | N22: =covAll!D22 -> -6.2983466e-11 | O22: =covAll!E22 -> -5.2497345e-11 | P22: =covAll!F22 -> -2.9339106e-10 | Q22: =covAll!G22 -> -1.4901364e-11 | R22: =covAll!H22 -> -2.7724439e-10 | S22: =covAll!I22 -> -2.3366394e-10 | T22: =covAll!J22 -> -5.7403646e-10 | ... AL22: =covAll!AB22 -> 1.4864617e-06
L23: 208/206 | M23: =covAll!C23 -> 1.3100978e-11 | N23: =covAll!D23 -> -1.5680446e-10 | O23: =covAll!E23 -> -1.2180154e-10 | P23: =covAll!F23 -> -1.2691152e-09 | Q23: =covAll!G23 -> -6.6227579e-11 | R23: =covAll!H23 -> -1.2525555e-09 | S23: =covAll!I23 -> -1.0487836e-09 | T23: =covAll!J23 -> -2.5821352e-09 | ... AL23: =covAll!AB23 -> 8.2298089e-06
K24: ET | L24: 206/238g | M24: =covAll!C24 -> -1.8936122e-13 | N24: =covAll!D24 -> -2.0025418e-12 | O24: =covAll!E24 -> -1.4669724e-12 | P24: =covAll!F24 -> 1.001418e-12 | Q24: =covAll!G24 -> 7.9686086e-14 | R24: =covAll!H24 -> 1.7967597e-12 | S24: =covAll!I24 -> 1.4538143e-12 | T24: =covAll!J24 -> 3.6226966e-12 | ... AL24: =covAll!AB24 -> -3.9795404e-08
K25: RP | L25: 206/238g | M25: =covAll!C25 -> -8.8776237e-13 | N25: =covAll!D25 -> -1.4432375e-11 | O25: =covAll!E25 -> -1.0773309e-11 | P25: =covAll!F25 -> -8.9572811e-12 | Q25: =covAll!G25 -> 1.2574539e-12 | R25: =covAll!H25 -> 2.4772326e-11 | S25: =covAll!I25 -> 2.0021393e-11 | T25: =covAll!J25 -> 4.8111527e-11 | ... AL25: =covAll!AB25 -> -1.893164e-07
K26: JMM | L26: 206/238g | M26: =covAll!C26 -> -5.192104e-13 | N26: =covAll!D26 -> -3.4922031e-12 | O26: =covAll!E26 -> -3.1505417e-12 | P26: =covAll!F26 -> 3.0481589e-12 | Q26: =covAll!G26 -> 2.2737161e-12 | R26: =covAll!H26 -> 4.1258938e-11 | S26: =covAll!I26 -> 3.4465114e-11 | T26: =covAll!J26 -> 8.3495968e-11 | ... AL26: =covAll!AB26 -> -1.1965074e-07
K27: ET tracers | L27: 202/205 | M27: =covAll!C27 -> 2.8302868e-11 | N27: =covAll!D27 -> 7.3438294e-10 | O27: =covAll!E27 -> 6.2238338e-10 | P27: =covAll!F27 -> 2.2038506e-09 | Q27: =covAll!G27 -> 1.7989514e-11 | R27: =covAll!H27 -> 3.5607402e-10 | S27: =covAll!I27 -> 2.903031e-10 | T27: =covAll!J27 -> 6.8800921e-10 | ... AJ27: =covAll!Z27 -> 1.4678778e-09 | AK27: =covAll!AA27+AK32 -> 7.0519308e-08 | AL27: =covAll!AB27+AL32 -> -5.662722e-06
L28: 235/205 | M28: =covAll!C28 -> -5.7932656e-09 | N28: =covAll!D28 -> -1.2752518e-07 | O28: =covAll!E28 -> -1.0127085e-07 | P28: =covAll!F28 -> -2.8391472e-07 | Q28: =covAll!G28 -> -1.3624037e-09 | R28: =covAll!H28 -> -2.6582354e-08 | S28: =covAll!I28 -> -2.2469068e-08 | T28: =covAll!J28 -> -4.9340079e-08 | ... AJ28: =covAll!Z28 -> -1.1965074e-07 | AK28: =covAll!AA28+AK33 -> -5.662722e-06 | AL28: =covAll!AB28+AL33 -> 0.00054362974
AG31: analytical uncertaintys from least squares minimization solution, to be added to systematic uncertainties above. | AJ31: covMeas: | AK31: 202/205 | AL31: 233/235
AJ32: 202/205 | AK32: 8.9619356e-11 | AL32: 4.923454e-09
AJ33: 233/235 | AK33: 4.9234391e-09 | AL33: 1.2018978e-06
D38: for ET535 only: | AH38: for ET2535 only:
F39: ET535 | AJ39: ET2535
F40: 204/205 | G40: 206/205 | H40: 207/205 | I40: 208/205 | J40: 233/235 | K40: 238/235 | M40: 235/205 | AJ40: 204/205 | AK40: 206/205 | AL40: 207/205 | AM40: 208/205 | AN40: 233/235 | AO40: 238/235 | AP40: 202/205 | AQ40: 235/205
B41: total covariance matrix (systematic and analytical uncertainties) | D41: ET535 | E41: 204/205 | F41: 8.7848722e-11 | G41: 1.5908858e-09 | H41: 1.3195772e-09 | I41: 3.202935e-09 | J41: 4.610964e-13 | K41: 5.5238195e-14 | L41: 0 | M41: -1.3624037e-09 | AF41: total covariance matrix (systematic and analytical uncertainties) | AH41: ET2535 | AI41: 204/205 | AJ41: 8.7848722e-11 | AK41: 1.5908858e-09 | AL41: 1.3195772e-09 | AM41: 3.202935e-09 | AN41: 4.610964e-13 | AO41: 5.5238195e-14 | AP41: 1.7989514e-11 | AQ41: -1.3624037e-09
E42: 206/205 | F42: 1.5908858e-09 | G42: 2.8907162e-08 | H42: 2.3940042e-08 | I42: 5.8160209e-08 | J42: 1.5724234e-11 | K42: 1.1283289e-12 | L42: 0 | M42: -2.6582354e-08 | AI42: 206/205 | AJ42: 1.5908858e-09 | AK42: 2.8907162e-08 | AL42: 2.3940042e-08 | AM42: 5.8160209e-08 | AN42: 1.5724234e-11 | AO42: 1.1283289e-12 | AP42: 3.5607402e-10 | AQ42: -2.6582354e-08
E43: 207/205 | F43: 1.3195772e-09 | G43: 2.3940042e-08 | H43: 1.9856214e-08 | I43: 4.822575e-08 | J43: 6.7713278e-12 | K43: 9.0507676e-13 | L43: 0 | M43: -2.2469068e-08 | AI43: 207/205 | AJ43: 1.3195772e-09 | AK43: 2.3940042e-08 | AL43: 1.9856214e-08 | AM43: 4.822575e-08 | AN43: 6.7713278e-12 | AO43: 9.0507676e-13 | AP43: 2.903031e-10 | AQ43: -2.2469068e-08
E44: 208/205 | F44: 3.202935e-09 | G44: 5.8160209e-08 | H44: 4.822575e-08 | I44: 1.1728846e-07 | J44: 4.1774129e-11 | K44: 2.295849e-12 | L44: 0 | M44: -4.9340079e-08 | AI44: 208/205 | AJ44: 3.202935e-09 | AK44: 5.8160209e-08 | AL44: 4.822575e-08 | AM44: 1.1728846e-07 | AN44: 4.1774129e-11 | AO44: 2.295849e-12 | AP44: 6.8800921e-10 | AQ44: -4.9340079e-08
E45: 233/235 | F45: 4.610964e-13 | G45: 1.5724234e-11 | H45: 6.7713278e-12 | I45: 4.1774129e-11 | J45: 2.8887958e-09 | K45: -1.2746879e-11 | L45: 0 | M45: 4.4618322e-07 | AI45: 233/235 | AJ45: 4.610964e-13 | AK45: 1.5724234e-11 | AL45: 6.7713278e-12 | AM45: 4.1774129e-11 | AN45: 2.8887958e-09 | AO45: -1.2746879e-11 | AP45: -2.0146104e-10 | AQ45: 4.4618322e-07
A46: (blank rows/columns are placeholders for 202/205 in ET2535 calculations) | E46: 238/235 | F46: 5.5238195e-14 | G46: 1.1283289e-12 | H46: 9.0507676e-13 | I46: 2.295849e-12 | J46: -1.2746879e-11 | K46: 1.5818262e-13 | L46: 0 | M46: -2.1274359e-09 | AI46: 238/235 | AJ46: 5.5238195e-14 | AK46: 1.1283289e-12 | AL46: 9.0507676e-13 | AM46: 2.295849e-12 | AN46: -1.2746879e-11 | AO46: 1.5818262e-13 | AP46: 2.792701e-12 | AQ46: -2.1274359e-09
...

Sheet covAll
A1: Covariance Matrix for MC trials (includes only systematic unct for 202/205 and 235/205) | C1: ET535 | G1: ET2535 | K1: RP DU | L1: CRM112a | M1: ET tracers | O1: NBS 981 | R1: NBS 982 | U1: Puratronic Pb | X1: ET | Y1: RP | Z1: JMM | AA1: ET tracers
C2: 204/205 | D2: 206/205 | E2: 207/205 | F2: 208/205 | G2: 204/205 | H2: 206/205 | I2: 207/205 | J2: 208/205 | K2: 238/235 | L2: 238/235 | M2: 233/235 | N2: 238/235 | O2: 204/206 | P2: 207/206 | Q2: 208/206 | R2: 204/206 | S2: 207/206 | T2: 208/206 | U2: 204/206 | V2: 207/206 | W2: 208/206 | X2: 206/238g | Y2: 206/238g | Z2: 206/238g | AA2: 202/205 | AB2: 235/205
A3: ET535 | B3: 204/205 | C3: 8.4401259e-11 | D3: 1.5541603e-09 | E3: 1.3041691e-09 | F3: 3.1932364e-09 | G3: 2.0206838e-12 | H3: 3.4280094e-11 | I3: 2.9582367e-11 | J3: 7.0834598e-11 | K3: 3.4511769e-09 | L3: 3.6041121e-09 | M3: -1.2805695e-11 | N3: -4.8913092e-15 | O3: -3.7990667e-13 | P3: 3.7607471e-12 | Q3: 1.5201564e-11 | R3: 1.5110591e-13 | S3: -1.0398825e-12 | T3: 1.7431024e-13 | U3: 1.2630877e-13 | V3: -1.7534032e-13 | W3: 1.3100978e-11 | X3: -1.8936122e-13 | Y3: -8.8776237e-13 | Z3: -5.192104e-13 | AA3: 2.8302868e-11 | AB3: -5.7932656e-09
B4: 206/205 | C4: 1.5541603e-09 | D4: 2.9643201e-08 | E4: 2.4477357e-08 | F4: 6.0583378e-08 | G4: 4.0956018e-11 | H4: 7.0629015e-10 | I4: 6.0856147e-10 | J4: 1.4691506e-09 | K4: 6.0096317e-08 | L4: 6.5224032e-08 | M4: -2.3167409e-10 | N4: 2.2899377e-14 | O4: 1.1732936e-12 | P4: 8.8824131e-12 | Q4: -5.7742548e-11 | R4: 7.6716014e-12 | S4: -3.8574072e-11 | T4: -9.4826056e-11 | U4: 1.2084213e-11 | V4: -6.2983466e-11 | W4: -1.5680446e-10 | X4: -2.0025418e-12 | Y4: -1.4432375e-11 | Z4: -3.4922031e-12 | AA4: 7.3438294e-10 | AB4: -1.2752518e-07
B5: 207/205 | C5: 1.3041691e-09 | D5: 2.4477357e-08 | E5: 2.0523433e-08 | F5: 5.061429e-08 | G5: 3.499379e-11 | H5: 6.0702033e-10 | I5: 5.2137398e-10 | J5: 1.2575324e-09 | K5: 4.3662818e-08 | L5: 5.4669682e-08 | M5: -1.9789096e-10 | N5: -2.3897245e-15 | O5: 6.4940111e-13 | P5: 6.7097011e-12 | Q5: -3.2522737e-11 | R5: 6.7188019e-12 | S5: -2.4440007e-11 | T5: -7.2843308e-11 | U5: 8.7644765e-12 | V5: -5.2497345e-11 | W5: -1.2180154e-10 | X5: -1.4669724e-12 | Y5: -1.0773309e-11 | Z5: -3.1505417e-12 | AA5: 6.2238338e-10 | AB5: -1.0127085e-07
B6: 208/205 | C6: 3.1932364e-09 | D6: 6.0583378e-08 | E6: 5.061429e-08 | F6: 1.2661291e-07 | G6: 8.3566949e-11 | H6: 1.4418618e-09 | I6: 1.2400239e-09 | J6: 2.9980738e-09 | K6: 3.8017982e-08 | L6: 1.1278997e-07 | M6: -4.0531615e-10 | N6: -1.5431809e-13 | O6: 2.8200402e-11 | P6: -1.6100223e-10 | Q6: -1.0667809e-09 | R6: 2.9807683e-11 | S6: -1.5251487e-10 | T6: -6.3397534e-10 | U6: 4.4902623e-11 | V6: -2.9339106e-10 | W6: -1.2691152e-09 | X6: 1.001418e-12 | Y6: -8.9572811e-12 | Z6: 3.0481589e-12 | AA6: 2.2038506e-09 | AB6: -2.8391472e-07
A7: ET2535 | B7: 204/205 | C7: 2.0206838e-12 | D7: 4.0956018e-11 | E7: 3.499379e-11 | F7: 8.3566949e-11 | G7: 8.7848722e-11 | H7: 1.5908858e-09 | I7: 1.3195772e-09 | J7: 3.202935e-09 | K7: -1.0413434e-09 | L7: -4.2772699e-10 | M7: 4.610964e-13 | N7: 5.5238195e-14 | O7: 1.6928661e-12 | P7: -1.0482122e-11 | Q7: -6.002277e-11 | R7: 4.2634161e-13 | S7: -1.0770441e-11 | T7: -5.076583e-11 | U7: 1.3565402e-12 | V7: -1.4901364e-11 | W7: -6.6227579e-11 | X7: 7.9686086e-14 | Y7: 1.2574539e-12 | Z7: 2.2737161e-12 | AA7: 1.7989514e-11 | AB7: -1.3624037e-09
B8: 206/205 | C8: 3.4280094e-11 | D8: 7.0629015e-10 | E8: 6.0702033e-10 | F8: 1.4418618e-09 | G8: 1.5908858e-09 | H8: 2.8907162e-08 | I8: 2.3940042e-08 | J8: 5.8160209e-08 | K8: -1.934794e-08 | L8: -8.1360571e-09 | M8: 1.5724234e-11 | N8: 1.1283289e-12 | O8: 3.1847588e-11 | P8: -1.9413496e-10 | Q8: -1.1238861e-09 | R8: 8.3536162e-12 | S8: -2.002014e-10 | T8: -9.3694742e-10 | U8: 2.5542971e-11 | V8: -2.7724439e-10 | W8: -1.2525555e-09 | X8: 1.7967597e-12 | Y8: 2.4772326e-11 | Z8: 4.1258938e-11 | AA8: 3.5607402e-10 | AB8: -2.6582354e-08
B9: 207/205 | C9: 2.9582367e-11 | D9: 6.0856147e-10 | E9: 5.2137398e-10 | F9: 1.2400239e-09 | G9: 1.3195772e-09 | H9: 2.3940042e-08 | I9: 1.9856214e-08 | J9: 4.822575e-08 | K9: -1.1940629e-08 | L9: -5.0733976e-09 | M9: 6.7713278e-12 | N9: 9.0507676e-13 | O9: 2.6790185e-11 | P9: -1.6487177e-10 | Q9: -9.4307706e-10 | R9: 6.8317153e-12 | S9: -1.6613193e-10 | T9: -7.7809227e-10 | U9: 2.1668274e-11 | V9: -2.3366394e-10 | W9: -1.0487836e-09 | X9: 1.4538143e-12 | Y9: 2.0021393e-11 | Z9: 3.4465114e-11 | AA9: 2.903031e-10 | AB9: -2.2469068e-08
B10: 208/205 | C10: 7.0834598e-11 | D10: 1.4691506e-09 | E10: 1.2575324e-09 | F10: 2.9980738e-09 | G10: 3.202935e-09 | H10: 5.8160209e-08 | I10: 4.822575e-08 | J10: 1.1728846e-07 | K10: -5.3169322e-08 | L10: -1.7021053e-08 | M10: 4.1774129e-11 | N10: 2.295849e-12 | O10: 6.5933468e-11 | P10: -3.9868408e-10 | Q10: -2.3101609e-09 | R10: 1.6666517e-11 | S10: -3.9809666e-10 | T10: -1.886617e-09 | U10: 5.2867495e-11 | V10: -5.7403646e-10 | W10: -2.5821352e-09 | X10: 3.6226966e-12 | Y10: 4.8111527e-11 | Z10: 8.3495968e-11 | AA10: 6.8800921e-10 | AB10: -4.9340079e-08
A11: RP DU | B11: 238/235 | C11: 3.4511769e-09 | D11: 6.0096317e-08 | E11: 4.3662818e-08 | F11: 3.8017982e-08 | G11: -1.0413434e-09 | H11: -1.934794e-08 | I11: -1.1940629e-08 | J11: -5.3169322e-08 | K11: 0.0018113428 | L11: 0.00041507187 | M11: -2.0409677e-06 | N11: 8.8730767e-09 | O11: 1.2401866e-08 | P11: -8.0622523e-08 | Q11: -4.3685561e-07 | R11: 3.4948632e-09 | S11: -3.7757072e-08 | T11: -1.5674446e-07 | U11: 9.7579239e-09 | V11: -7.4030033e-08 | W11: -3.770309e-07 | X11: 1.0829106e-09 | Y11: 3.9610695e-09 | Z11: 9.2126537e-09 | AA11: 2.6452497e-07 | AB11: -0.00032597222
A12: CRM112a | B12: 238/235 | C12: 3.6041121e-09 | D12: 6.5224032e-08 | E12: 5.4669682e-08 | F12: 1.1278997e-07 | G12: -4.2772699e-10 | H12: -8.1360571e-09 | I12: -5.0733976e-09 | J12: -1.7021053e-08 | K12: 0.00041507187 | L12: 0.0001387567 | M12: -5.7935923e-07 | N12: 2.536979e-09 | O12: 3.8214611e-09 | P12: -2.5699204e-08 | Q12: -1.2956384e-07 | R12: 9.6638648e-10 | S12: -1.1217973e-08 | T12: -4.4635861e-08 | U12: 2.1939988e-09 | V12: -2.570338e-08 | W12: -1.0101094e-07 | X12: 4.364312e-10 | Y12: 1.2951795e-09 | Z12: 2.3674294e-09 | AA12: 7.7278725e-08 | AB12: -9.2077836e-05
A13: ET tracers | B13: 233/235 | C13: -1.2805695e-11 | D13: -2.3167409e-10 | E13: -1.9789096e-10 | F13: -4.0531615e-10 | G13: 4.610964e-13 | H13: 1.5724234e-11 | I13: 6.7713278e-12 | J13: 4.1774129e-11 | K13: -2.0409677e-06 | L13: -5.7935923e-07 | M13: 2.8887958e-09 | N13: -1.2746879e-11 | O13: -9.9999114e-12 | P13: 6.9527887e-11 | Q13: 3.5290053e-10 | R13: -1.8290458e-12 | S13: 3.0169934e-11 | T13: 1.0450066e-10 | U13: -5.285282e-12 | V13: 6.6738635e-11 | W13: 2.444151e-10 | X13: -4.3269518e-13 | Y13: 3.5356352e-13 | Z13: -8.3390159e-12 | AA13: -2.0146104e-10 | AB13: 4.4618322e-07
B14: 238/235 | C14: -4.8913092e-15 | D14: 2.2899377e-14 | E14: -2.3897245e-15 | F14: -1.5431809e-13 | G14: 5.5238195e-14 | H14: 1.1283289e-12 | I14: 9.0507676e-13 | J14: 2.295849e-12 | K14: 8.8730767e-09 | L14: 2.536979e-09 | M14: -1.2746879e-11 | N14: 1.5818262e-13 | O14: 1.2628233e-13 | P14: -7.8251946e-13 | Q14: -4.3137158e-12 | R14: 4.9887236e-14 | S14: -4.2531536e-13 | T14: -1.8240737e-12 | U14: 1.1359948e-13 | V14: -7.0701693e-13 | W14: -4.1322022e-12 | X14: 1.6305043e-14 | Y14: 6.9284958e-14 | Z14: 9.5326714e-14 | AA14: 2.792701e-12 | AB14: -2.1274359e-09
A15: NBS 981 | B15: 204/206 | C15: -3.7990667e-13 | D15: 1.1732936e-12 | E15: 6.4940111e-13 | F15: 2.8200402e-11 | G15: 1.6928661e-12 | H15: 3.1847588e-11 | I15: 2.6790185e-11 | J15: 6.5933468e-11 | K15: 1.2401866e-08 | L15: 3.8214611e-09 | M15: -9.9999114e-12 | N15: 1.2628233e-13 | O15: 1.1933737e-10 | P15: -7.7283908e-10 | Q15: -4.260545e-09 | R15: 5.2061596e-11 | S15: -3.8983371e-10 | T15: -2.0055944e-09 | U15: 1.1144912e-10 | V15: -7.5654228e-10 | W15: -4.1914582e-09 | X15: 1.9989397e-11 | Y15: 8.9142028e-11 | Z15: 5.9715301e-11 | AA15: 2.8753492e-09 | AB15: -2.325822e-07
B16: 207/206 | C16: 3.7607471e-12 | D16: 8.8824131e-12 | E16: 6.7097011e-12 | F16: -1.6100223e-10 | G16: -1.0482122e-11 | H16: -1.9413496e-10 | I16: -1.6487177e-10 | J16: -3.9868408e-10 | K16: -8.0622523e-08 | L16: -2.5699204e-08 | M16: 6.9527887e-11 | N16: -7.8251946e-13 | O16: -7.7283908e-10 | P16: 5.2792034e-09 | Q16: 2.8373261e-08 | R16: -3.5447191e-10 | S16: 2.3898418e-09 | T16: 1.2696598e-08 | U16: -7.2940593e-10 | V16: 5.0249315e-09 | W16: 2.76824e-08 | X16: -1.3350924e-10 | Y16: -5.5962906e-10 | Z16: -3.9595691e-10 | AA16: -1.8908491e-08 | AB16: 1.4891812e-06
B17: 208/206 | C17: 1.5201564e-11 | D17: -5.7742548e-11 | E17: -3.2522737e-11 | F17: -1.0667809e-09 | G17: -6.002277e-11 | H17: -1.1238861e-09 | I17: -9.4307706e-10 | J17: -2.3101609e-09 | K17: -4.3685561e-07 | L17: -1.2956384e-07 | M17: 3.5290053e-10 | N17: -4.3137158e-12 | O17: -4.260545e-09 | P17: 2.8373261e-08 | Q17: 1.5515337e-07 | R17: -1.917171e-09 | S17: 1.3563823e-08 | T17: 7.1117986e-08 | U17: -4.0146536e-09 | V17: 2.7468859e-08 | W17: 1.5202305e-07 | X17: -7.2847917e-10 | Y17: -3.1468758e-09 | Z17: -2.1695982e-09 | AA17: -1.0402851e-07 | AB17: 8.2935988e-06
A18: NBS 982 | B18: 204/206 | C18: 1.5110591e-13 | D18: 7.6716014e-12 | E18: 6.7188019e-12 | F18: 2.9807683e-11 | G18: 4.2634161e-13 | H18: 8.3536162e-12 | I18: 6.8317153e-12 | J18: 1.6666517e-11 | K18: 3.4948632e-09 | L18: 9.6638648e-10 | M18: -1.8290458e-12 | N18: 4.9887236e-14 | O18: 5.2061596e-11 | P18: -3.5447191e-10 | Q18: -1.917171e-09 | R18: 2.6018844e-11 | S18: -1.5417582e-10 | T18: -8.4911595e-10 | U18: 4.9613982e-11 | V18: -3.4061043e-10 | W18: -1.8812044e-09 | X18: 9.0140597e-12 | Y18: 3.7199393e-11 | Z18: 2.6838083e-11 | AA18: 1.2796958e-09 | AB18: -9.9146642e-08
B19: 207/206 | C19: -1.0398825e-12 | D19: -3.8574072e-11 | E19: -2.4440007e-11 | F19: -1.5251487e-10 | G19: -1.0770441e-11 | H19: -2.002014e-10 | I19: -1.6613193e-10 | J19: -3.9809666e-10 | K19: -3.7757072e-08 | L19: -1.1217973e-08 | M19: 3.0169934e-11 | N19: -4.2531536e-13 | O19: -3.8983371e-10 | P19: 2.3898418e-09 | Q19: 1.3563823e-08 | R19: -1.5417582e-10 | S19: 1.6660945e-09 | T19: 7.30988e-09 | U19: -3.6278069e-10 | V19: 2.4511959e-09 | W19: 1.3531118e-08 | X19: -6.341015e-11 | Y19: -3.3546397e-10 | Z19: -1.9229909e-10 | AA19: -9.3983037e-09 | AB19: 8.3592055e-07
B20: 208/206 | C20: 1.7431024e-13 | D20: -9.4826056e-11 | E20: -7.2843308e-11 | F20: -6.3397534e-10 | G20: -5.076583e-11 | H20: -9.3694742e-10 | I20: -7.7809227e-10 | J20: -1.886617e-09 | K20: -1.5674446e-07 | L20: -4.4635861e-08 | M20: 1.0450066e-10 | N20: -1.8240737e-12 | O20: -2.0055944e-09 | P20: 1.2696598e-08 | Q20: 7.1117986e-08 | R20: -8.4911595e-10 | S20: 7.30988e-09 | T20: 3.6154634e-08 | U20: -1.8789187e-09 | V20: 1.2729472e-08 | W20: 7.056289e-08 | X20: -3.335086e-10 | Y20: -1.6225995e-09 | Z20: -1.0023019e-09 | AA20: -4.895551e-08 | AB20: 4.1048319e-06
A21: Puratronic Pb | B21: 204/206 | C21: 1.2630877e-13 | D21: 1.2084213e-11 | E21: 8.7644765e-12 | F21: 4.4902623e-11 | G21: 1.3565402e-12 | H21: 2.5542971e-11 | I21: 2.1668274e-11 | J21: 5.2867495e-11 | K21: 9.7579239e-09 | L21: 2.1939988e-09 | M21: -5.285282e-12 | N21: 1.1359948e-13 | O21: 1.1144912e-10 | P21: -7.2940593e-10 | Q21: -4.0146536e-09 | R21: 4.9613982e-11 | S21: -3.6278069e-10 | T21: -1.8789187e-09 | U21: 1.0961535e-10 | V21: -7.3272889e-10 | W21: -4.0363436e-09 | X21: 1.8833734e-11 | Y21: 8.3343702e-11 | Z21: 5.7563004e-11 | AA21: 2.7224502e-09 | AB21: -2.1870257e-07
B22: 207/206 | C22: -1.7534032e-13 | D22: -6.2983466e-11 | E22: -5.2497345e-11 | F22: -2.9339106e-10 | G22: -1.4901364e-11 | H22: -2.7724439e-10 | I22: -2.3366394e-10 | J22: -5.7403646e-10 | K22: -7.4030033e-08 | L22: -2.570338e-08 | M22: 6.6738635e-11 | N22: -7.0701693e-13 | O22: -7.5654228e-10 | P22: 5.0249315e-09 | Q22: 2.7468859e-08 | R22: -3.4061043e-10 | S22: 2.4511959e-09 | T22: 1.2729472e-08 | U22: -7.3272889e-10 | V22: 5.4375966e-09 | W22: 2.7677284e-08 | X22: -1.2870764e-10 | Y22: -5.6147218e-10 | Z22: -4.0016859e-10 | AA22: -1.8617636e-08 | AB22: 1.4864617e-06
B23: 208/206 | C23: 1.3100978e-11 | D23: -1.5680446e-10 | E23: -1.2180154e-10 | F23: -1.2691152e-09 | G23: -6.6227579e-11 | H23: -1.2525555e-09 | I23: -1.0487836e-09 | J23: -2.5821352e-09 | K23: -3.770309e-07 | L23: -1.0101094e-07 | M23: 2.444151e-10 | N23: -4.1322022e-12 | O23: -4.1914582e-09 | P23: 2.76824e-08 | Q23: 1.5202305e-07 | R23: -1.8812044e-09 | S23: 1.3531118e-08 | T23: 7.056289e-08 | U23: -4.0363436e-09 | V23: 2.7677284e-08 | W23: 1.5288175e-07 | X23: -7.1261941e-10 | Y23: -3.1202687e-09 | Z23: -2.1787127e-09 | AA23: -1.0291152e-07 | AB23: 8.2298089e-06
A24: ET | B24: 206/238g | C24: -1.8936122e-13 | D24: -2.0025418e-12 | E24: -1.4669724e-12 | F24: 1.001418e-12 | G24: 7.9686086e-14 | H24: 1.7967597e-12 | I24: 1.4538143e-12 | J24: 3.6226966e-12 | K24: 1.0829106e-09 | L24: 4.364312e-10 | M24: -4.3269518e-13 | N24: 1.6305043e-14 | O24: 1.9989397e-11 | P24: -1.3350924e-10 | Q24: -7.2847917e-10 | R24: 9.0140597e-12 | S24: -6.341015e-11 | T24: -3.335086e-10 | U24: 1.8833734e-11 | V24: -1.2870764e-10 | W24: -7.1261941e-10 | X24: 3.7154774e-12 | Y24: 1.6153904e-11 | Z24: 1.0160835e-11 | AA24: 4.8813948e-10 | AB24: -3.9795404e-08
A25: RP | B25: 206/238g | C25: -8.8776237e-13 | D25: -1.4432375e-11 | E25: -1.0773309e-11 | F25: -8.9572811e-12 | G25: 1.2574539e-12 | H25: 2.4772326e-11 | I25: 2.0021393e-11 | J25: 4.8111527e-11 | K25: 3.9610695e-09 | L25: 1.2951795e-09 | M25: 3.5356352e-13 | N25: 6.9284958e-14 | O25: 8.9142028e-11 | P25: -5.5962906e-10 | Q25: -3.1468758e-09 | R25: 3.7199393e-11 | S25: -3.3546397e-10 | T25: -1.6225995e-09 | U25: 8.3343702e-11 | V25: -5.6147218e-10 | W25: -3.1202687e-09 | X25: 1.6153904e-11 | Y25: 8.1298493e-11 | Z25: 4.4265971e-11 | AA25: 2.1679272e-09 | AB25: -1.893164e-07
A26: JMM | B26: 206/238g | C26: -5.192104e-13 | D26: -3.4922031e-12 | E26: -3.1505417e-12 | F26: 3.0481589e-12 | G26: 2.2737161e-12 | H26: 4.1258938e-11 | I26: 3.4465114e-11 | J26: 8.3495968e-11 | K26: 9.2126537e-09 | L26: 2.3674294e-09 | M26: -8.3390159e-12 | N26: 9.5326714e-14 | O26: 5.9715301e-11 | P26: -3.9595691e-10 | Q26: -2.1695982e-09 | R26: 2.6838083e-11 | S26: -1.9229909e-10 | T26: -1.0023019e-09 | U26: 5.7563004e-11 | V26: -4.0016859e-10 | W26: -2.1787127e-09 | X26: 1.0160835e-11 | Y26: 4.4265971e-11 | Z26: 3.4475665e-11 | AA26: 1.4678778e-09 | AB26: -1.1965074e-07
A27: ET tracers | B27: 202/205 | C27: 2.8302868e-11 | D27: 7.3438294e-10 | E27: 6.2238338e-10 | F27: 2.2038506e-09 | G27: 1.7989514e-11 | H27: 3.5607402e-10 | I27: 2.903031e-10 | J27: 6.8800921e-10 | K27: 2.6452497e-07 | L27: 7.7278725e-08 | M27: -2.0146104e-10 | N27: 2.792701e-12 | O27: 2.8753492e-09 | P27: -1.8908491e-08 | Q27: -1.0402851e-07 | R27: 1.2796958e-09 | S27: -9.3983037e-09 | T27: -4.895551e-08 | U27: 2.7224502e-09 | V27: -1.8617636e-08 | W27: -1.0291152e-07 | X27: 4.8813948e-10 | Y27: 2.1679272e-09 | Z27: 1.4678778e-09 | AA27: 7.0429689e-08 | AB27: -5.6676455e-06
B28: 235/205 | C28: -5.7932656e-09 | D28: -1.2752518e-07 | E28: -1.0127085e-07 | F28: -2.8391472e-07 | G28: -1.3624037e-09 | H28: -2.6582354e-08 | I28: -2.2469068e-08 | J28: -4.9340079e-08 | K28: -0.00032597222 | L28: -9.2077836e-05 | M28: 4.4618322e-07 | N28: -2.1274359e-09 | O28: -2.325822e-07 | P28: 1.4891812e-06 | Q28: 8.2935988e-06 | R28: -9.9146642e-08 | S28: 8.3592055e-07 | T28: 4.1048319e-06 | U28: -2.1870257e-07 | V28: 1.4864617e-06 | W28: 8.2298089e-06 | X28: -3.9795404e-08 | Y28: -1.893164e-07 | Z28: -1.1965074e-07 | AA28: -5.6676455e-06 | AB28: 0.00054242784
